Workbook

Sheet INPUT_DATA
A1: ID | B1: Type | C1: Link | D1: Address | E1: Distance (m) | F1: Price (€) | G1: Size (m2) | H1: Price per m2 (€) | I1: Bedrooms | J1: Bathrooms | K1: Floor | L1: Elevator | M1: Condition | N1: Year | O1: Terrace | P1: Parking | Q1: Listing Date | R1: Days on Market | S1: Notes
A2: 1 | B2: Rent | C2: https://www.idealista.com/inmueble/108875567/ | D2: Alquiler de piso en Huertas-Cortes | F2: 1450 | G2: 60 | H2: =IFERROR(IF(AND(F2>0,G2>0),F2/G2,""),"") | I2: 2 | J2: 1 | K2: principal | Q2: 46138 | R2: =IFERROR(IF(Q2="","",TODAY()-Q2),"")
A3: 2 | B3: Rent | C3: https://www.idealista.com/inmueble/108138954/ | D3: Alquiler de piso en Palacio | F3: 2350 | G3: 85 | H3: =IFERROR(IF(AND(F3>0,G3>0),F3/G3,""),"") | I3: 3 | J3: 2 | K3: principal | Q3: 46138 | R3: =IFERROR(IF(Q3="","",TODAY()-Q3),"")
A4: 3 | B4: Rent | C4: https://www.idealista.com/inmueble/111294791/ | D4: Alquiler de piso en Calle de Valencia, 18 | F4: 1990 | G4: 95 | H4: =IFERROR(IF(AND(F4>0,G4>0),F4/G4,""),"") | I4: 3 | J4: 1 | K4: principal | R4: =IFERROR(IF(Q4="","",TODAY()-Q4),"")
A5: 4 | B5: Rent | C5: https://www.idealista.com/inmueble/109092604/ | D5: Alquiler de piso en Calle de Carlos Arniches, 31 | F5: 1150 | G5: 50 | H5: =IFERROR(IF(AND(F5>0,G5>0),F5/G5,""),"") | I5: 2 | J5: 1 | K5: principal | R5: =IFERROR(IF(Q5="","",TODAY()-Q5),"")
A6: 5 | B6: Rent | C6: https://www.idealista.com/inmueble/37063395/ | D6: Alquiler de estudio en Calle de Almadén, 5 | F6: 1100 | G6: 32 | H6: =IFERROR(IF(AND(F6>0,G6>0),F6/G6,""),"") | J6: 1 | K6: principal | R6: =IFERROR(IF(Q6="","",TODAY()-Q6),"")
A7: 6 | B7: Rent | C7: https://www.idealista.com/inmueble/111296556/ | D7: Alquiler de piso en Calle de Concepción Jerónima, 11 | F7: 1700 | G7: 86 | H7: =IFERROR(IF(AND(F7>0,G7>0),F7/G7,""),"") | I7: 2 | J7: 1 | K7: principal | Q7: 46138 | R7: =IFERROR(IF(Q7="","",TODAY()-Q7),"")
A8: 7 | B8: Rent | C8: https://www.idealista.com/inmueble/111296292/ | D8: Alquiler de estudio en Plaza de Cascorro | F8: 1170 | G8: 61 | H8: =IFERROR(IF(AND(F8>0,G8>0),F8/G8,""),"") | J8: 1 | K8: principal | R8: =IFERROR(IF(Q8="","",TODAY()-Q8),"")
A9: 8 | B9: Rent | C9: https://www.idealista.com/inmueble/111296145/ | D9: Alquiler de piso en Calle de la Ballesta | F9: 1300 | G9: 35 | H9: =IFERROR(IF(AND(F9>0,G9>0),F9/G9,""),"") | I9: 2 | J9: 1 | K9: principal | R9: =IFERROR(IF(Q9="","",TODAY()-Q9),"")
A10: 9 | B10: Rent | C10: https://www.idealista.com/inmueble/111296139/ | D10: Alquiler de piso en Calle de Cuchilleros | F10: 2600 | G10: 100 | H10: =IFERROR(IF(AND(F10>0,G10>0),F10/G10,""),"") | I10: 2 | J10: 2 | K10: principal | R10: =IFERROR(IF(Q10="","",TODAY()-Q10),"")
A11: 10 | B11: Rent | C11: https://www.idealista.com/inmueble/94572701/ | D11: Alquiler de piso en Huertas-Cortes | F11: 1150 | G11: 45 | H11: =IFERROR(IF(AND(F11>0,G11>0),F11/G11,""),"") | I11: 1 | J11: 1 | K11: principal | R11: =IFERROR(IF(Q11="","",TODAY()-Q11),"")
A12: 11 | B12: Rent | C12: https://www.idealista.com/inmueble/111295967/ | D12: Alquiler de estudio en Calle de Preciados, 34 | F12: 1450 | G12: 30 | H12: =IFERROR(IF(AND(F12>0,G12>0),F12/G12,""),"") | J12: 1 | K12: principal | R12: =IFERROR(IF(Q12="","",TODAY()-Q12),"")
A13: 12 | B13: Rent | C13: https://www.idealista.com/inmueble/111295916/ | D13: Alquiler de estudio en Calle de San Marcos s/n | F13: 1600 | G13: 35 | H13: =IFERROR(IF(AND(F13>0,G13>0),F13/G13,""),"") | J13: 1 | K13: principal | R13: =IFERROR(IF(Q13="","",TODAY()-Q13),"")
A14: 13 | B14: Rent | C14: https://www.idealista.com/inmueble/111295915/ | D14: Alquiler de piso en Calle de Santa María, 36 | F14: 1700 | G14: 65 | H14: =IFERROR(IF(AND(F14>0,G14>0),F14/G14,""),"") | I14: 2 | J14: 1 | K14: principal | R14: =IFERROR(IF(Q14="","",TODAY()-Q14),"")
A15: 14 | B15: Rent | C15: https://www.idealista.com/inmueble/111295893/ | D15: Alquiler de piso en Calle del Conde de Romanones s/n | F15: 1695 | G15: 60 | H15: =IFERROR(IF(AND(F15>0,G15>0),F15/G15,""),"") | I15: 2 | J15: 1 | K15: principal | R15: =IFERROR(IF(Q15="","",TODAY()-Q15),"")
A16: 15 | B16: Rent | C16: https://www.idealista.com/inmueble/111294588/ | D16: Alquiler de piso en Amparo, 29 | F16: 1100 | G16: 54 | H16: =IFERROR(IF(AND(F16>0,G16>0),F16/G16,""),"") | I16: 1 | J16: 1 | K16: principal | R16: =IFERROR(IF(Q16="","",TODAY()-Q16),"")
A17: 16 | B17: Rent | C17: https://www.idealista.com/inmueble/99174937/ | D17: Alquiler de estudio en Calle del Salitre, 44 | F17: 850 | G17: 25 | H17: =IFERROR(IF(AND(F17>0,G17>0),F17/G17,""),"") | J17: 1 | K17: principal | R17: =IFERROR(IF(Q17="","",TODAY()-Q17),"")
A18: 17 | B18: Rent | C18: https://www.idealista.com/inmueble/111293407/ | D18: Alquiler de piso en Recoletos | F18: 5000 | G18: 225 | H18: =IFERROR(IF(AND(F18>0,G18>0),F18/G18,""),"") | I18: 3 | J18: 3 | K18: principal | Q18: 46138 | R18: =IFERROR(IF(Q18="","",TODAY()-Q18),"")
A19: 18 | B19: Rent | C19: https://www.idealista.com/inmueble/104791906/ | D19: Alquiler de piso en Calle de Fuencarral, 9 | F19: 2300 | G19: 90 | H19: =IFERROR(IF(AND(F19>0,G19>0),F19/G19,""),"") | I19: 1 | J19: 1 | K19: principal | R19: =IFERROR(IF(Q19="","",TODAY()-Q19),"")
A20: 19 | B20: Rent | C20: https://www.idealista.com/inmueble/111292918/ | D20: Alquiler de piso en Plaza de Tirso de Molina | F20: 1200 | G20: 40 | H20: =IFERROR(IF(AND(F20>0,G20>0),F20/G20,""),"") | I20: 1 | J20: 1 | K20: principal | R20: =IFERROR(IF(Q20="","",TODAY()-Q20),"")
A21: 20 | B21: Rent | C21: https://www.idealista.com/inmueble/111292908/ | D21: Alquiler de estudio en Plaza de Tirso de Molina | F21: 850 | G21: 30 | H21: =IFERROR(IF(AND(F21>0,G21>0),F21/G21,""),"") | J21: 1 | K21: principal | R21: =IFERROR(IF(Q21="","",TODAY()-Q21),"")
A22: 21 | B22: Rent | C22: https://www.idealista.com/inmueble/111291767/ | D22: Alquiler de piso en Calle de la Madera, 8 | F22: 1000 | G22: 30 | H22: =IFERROR(IF(AND(F22>0,G22>0),F22/G22,""),"") | I22: 1 | J22: 1 | K22: principal | R22: =IFERROR(IF(Q22="","",TODAY()-Q22),"")
A23: 22 | B23: Rent | C23: https://www.idealista.com/inmueble/111289237/ | D23: Alquiler de piso en Calle del Prado, 3 | F23: 1950 | G23: 55 | H23: =IFERROR(IF(AND(F23>0,G23>0),F23/G23,""),"") | I23: 1 | J23: 1 | K23: principal | R23: =IFERROR(IF(Q23="","",TODAY()-Q23),"")
A24: 23 | B24: Rent | C24: https://www.idealista.com/inmueble/111289497/ | D24: Alquiler de ático en Calle de la Libertad, 25 | F24: 1400 | G24: 55 | H24: =IFERROR(IF(AND(F24>0,G24>0),F24/G24,""),"") | I24: 1 | J24: 1 | K24: ático | R24: =IFERROR(IF(Q24="","",TODAY()-Q24),"")
A25: 24 | B25: Rent | C25: https://www.idealista.com/inmueble/111278729/ | D25: Alquiler de piso en Calle de Santa María | F25: 1250 | G25: 30 | H25: =IFERROR(IF(AND(F25>0,G25>0),F25/G25,""),"") | I25: 1 | J25: 1 | K25: principal | R25: =IFERROR(IF(Q25="","",TODAY()-Q25),"")
A26: 25 | B26: Rent | C26: https://www.idealista.com/inmueble/111292394/ | D26: Alquiler de piso en Calle de Argumosa | F26: 1300 | G26: 51 | H26: =IFERROR(IF(AND(F26>0,G26>0),F26/G26,""),"") | I26: 1 | J26: 1 | K26: principal | R26: =IFERROR(IF(Q26="","",TODAY()-Q26),"")
A27: 26 | B27: Rent | C27: https://www.idealista.com/inmueble/111279789/ | D27: Alquiler de piso en Lavapiés-Embajadores | F27: 750 | G27: 21 | H27: =IFERROR(IF(AND(F27>0,G27>0),F27/G27,""),"") | I27: 1 | J27: 1 | K27: principal | R27: =IFERROR(IF(Q27="","",TODAY()-Q27),"")
A28: 27 | B28: Rent | C28: https://www.idealista.com/inmueble/111292308/ | D28: Alquiler de piso en Calle de Hortaleza | F28: 1250 | G28: 35 | H28: =IFERROR(IF(AND(F28>0,G28>0),F28/G28,""),"") | I28: 1 | J28: 1 | K28: principal | R28: =IFERROR(IF(Q28="","",TODAY()-Q28),"")
A29: 28 | B29: Rent | C29: https://www.idealista.com/inmueble/111291465/ | D29: Alquiler de estudio en Lavapiés-Embajadores | F29: 1200 | G29: 30 | H29: =IFERROR(IF(AND(F29>0,G29>0),F29/G29,""),"") | J29: 1 | K29: principal | R29: =IFERROR(IF(Q29="","",TODAY()-Q29),"")
A30: 29 | B30: Rent | C30: https://www.idealista.com/inmueble/111291442/ | D30: Alquiler de piso en Huertas-Cortes | F30: 1300 | G30: 54 | H30: =IFERROR(IF(AND(F30>0,G30>0),F30/G30,""),"") | I30: 1 | J30: 1 | K30: principal | R30: =IFERROR(IF(Q30="","",TODAY()-Q30),"")
A31: 30 | B31: Rent | C31: https://www.idealista.com/inmueble/111236832/ | D31: Alquiler de ático en Calle de la Cabeza, 40 | F31: 1250 | G31: 63 | H31: =IFERROR(IF(AND(F31>0,G31>0),F31/G31,""),"") | I31: 1 | J31: 1 | K31: ático | R31: =IFERROR(IF(Q31="","",TODAY()-Q31),"")
H32: =IFERROR(IF(AND(F32>0,G32>0),F32/G32,""),"") | R32: =IFERROR(IF(Q32="","",TODAY()-Q32),"")
H33: =IFERROR(IF(AND(F33>0,G33>0),F33/G33,""),"") | R33: =IFERROR(IF(Q33="","",TODAY()-Q33),"")
H34: =IFERROR(IF(AND(F34>0,G34>0),F34/G34,""),"") | R34: =IFERROR(IF(Q34="","",TODAY()-Q34),"")
H35: =IFERROR(IF(AND(F35>0,G35>0),F35/G35,""),"") | R35: =IFERROR(IF(Q35="","",TODAY()-Q35),"")
H36: =IFERROR(IF(AND(F36>0,G36>0),F36/G36,""),"") | R36: =IFERROR(IF(Q36="","",TODAY()-Q36),"")
H37: =IFERROR(IF(AND(F37>0,G37>0),F37/G37,""),"") | R37: =IFERROR(IF(Q37="","",TODAY()-Q37),"")
H38: =IFERROR(IF(AND(F38>0,G38>0),F38/G38,""),"") | R38: =IFERROR(IF(Q38="","",TODAY()-Q38),"")
H39: =IFERROR(IF(AND(F39>0,G39>0),F39/G39,""),"") | R39: =IFERROR(IF(Q39="","",TODAY()-Q39),"")
H40: =IFERROR(IF(AND(F40>0,G40>0),F40/G40,""),"") | R40: =IFERROR(IF(Q40="","",TODAY()-Q40),"")
...

Sheet ANALYSIS
A1: REAL ESTATE INVESTMENT — ANALYSIS DASHBOARD
A2: All metrics auto-update from the INPUT_DATA sheet. Empty rows are ignored.
A4: A) SALES ANALYSIS (price per m²)
A5: Average Price per m² (Sale) | B5: =IFERROR(AVERAGEIFS(INPUT_DATA!$H$2:$H$201,INPUT_DATA!$B$2:$B$201,"Sale",INPUT_DATA!$H$2:$H$201,">0"),0)
A6: Median Price per m² (Sale) | B6: =IFERROR(AGGREGATE(17,6,INPUT_DATA!$H$2:$H$201/((INPUT_DATA!$B$2:$B$201="Sale")*(INPUT_DATA!$H$2:$H$201>0)),2),0)
A7: Min Price per m² (Sale) | B7: =IFERROR(MINIFS(INPUT_DATA!$H$2:$H$201,INPUT_DATA!$B$2:$B$201,"Sale",INPUT_DATA!$H$2:$H$201,">0"),0)
A8: Max Price per m² (Sale) | B8: =IFERROR(MAXIFS(INPUT_DATA!$H$2:$H$201,INPUT_DATA!$B$2:$B$201,"Sale",INPUT_DATA!$H$2:$H$201,">0"),0)
A9: Count (Sale listings) | B9: =COUNTIFS(INPUT_DATA!$B$2:$B$201,"Sale",INPUT_DATA!$F$2:$F$201,">0")
A11: B) RENT ANALYSIS (monthly €)
A12: Avg Monthly Rent | B12: =IFERROR(AVERAGEIFS(INPUT_DATA!$F$2:$F$201,INPUT_DATA!$B$2:$B$201,"Rent",INPUT_DATA!$F$2:$F$201,">0"),0)
A13: Avg Rent per m² | B13: =IFERROR(AVERAGEIFS(INPUT_DATA!$H$2:$H$201,INPUT_DATA!$B$2:$B$201,"Rent",INPUT_DATA!$H$2:$H$201,">0"),0)
A14: Median Rent per m² | B14: =IFERROR(AGGREGATE(17,6,INPUT_DATA!$H$2:$H$201/((INPUT_DATA!$B$2:$B$201="Rent")*(INPUT_DATA!$H$2:$H$201>0)),2),0)
A15: Count (Rent listings) | B15: =COUNTIFS(INPUT_DATA!$B$2:$B$201,"Rent",INPUT_DATA!$F$2:$F$201,">0")
A17: C) YIELD ESTIMATION
A18: Avg Sale Price (whole property) | B18: =IFERROR(AVERAGEIFS(INPUT_DATA!$F$2:$F$201,INPUT_DATA!$B$2:$B$201,"Sale",INPUT_DATA!$F$2:$F$201,">0"),0)
A19: Annualised Rent (B12×12) | B19: =B12*12
A20: Gross Rental Yield | B20: =IFERROR(IF(B18>0,B19/B18,0),0) | C20: ← headline KPI
A22: D) MARKET SEGMENTATION (Sale listings)
A23: Condition | B23: Avg €/m² | C23: Median €/m² | D23: # Listings
A24: New | B24: =IFERROR(AVERAGEIFS(INPUT_DATA!$H$2:$H$201,INPUT_DATA!$B$2:$B$201,"Sale",INPUT_DATA!$M$2:$M$201,"New",INPUT_DATA!$H$2:$H$201,">0"),0) | C24: =IFERROR(AGGREGATE(17,6,INPUT_DATA!$H$2:$H$201/((INPUT_DATA!$B$2:$B$201="Sale")*(INPUT_DATA!$M$2:$M$201="New")*(INPUT_DATA!$H$2:$H$201>0)),2),0) | D24: =COUNTIFS(INPUT_DATA!$B$2:$B$201,"Sale",INPUT_DATA!$M$2:$M$201,"New",INPUT_DATA!$F$2:$F$201,">0")
A25: Renovated | B25: =IFERROR(AVERAGEIFS(INPUT_DATA!$H$2:$H$201,INPUT_DATA!$B$2:$B$201,"Sale",INPUT_DATA!$M$2:$M$201,"Renovated",INPUT_DATA!$H$2:$H$201,">0"),0) | C25: =IFERROR(AGGREGATE(17,6,INPUT_DATA!$H$2:$H$201/((INPUT_DATA!$B$2:$B$201="Sale")*(INPUT_DATA!$M$2:$M$201="Renovated")*(INPUT_DATA!$H$2:$H$201>0)),2),0) | D25: =COUNTIFS(INPUT_DATA!$B$2:$B$201,"Sale",INPUT_DATA!$M$2:$M$201,"Renovated",INPUT_DATA!$F$2:$F$201,">0")
A26: To renovate | B26: =IFERROR(AVERAGEIFS(INPUT_DATA!$H$2:$H$201,INPUT_DATA!$B$2:$B$201,"Sale",INPUT_DATA!$M$2:$M$201,"To renovate",INPUT_DATA!$H$2:$H$201,">0"),0) | C26: =IFERROR(AGGREGATE(17,6,INPUT_DATA!$H$2:$H$201/((INPUT_DATA!$B$2:$B$201="Sale")*(INPUT_DATA!$M$2:$M$201="To renovate")*(INPUT_DATA!$H$2:$H$201>0)),2),0) | D26: =COUNTIFS(INPUT_DATA!$B$2:$B$201,"Sale",INPUT_DATA!$M$2:$M$201,"To renovate",INPUT_DATA!$F$2:$F$201,">0")
A28: E) CALCULATION NOTES
A29: Medians use AGGREGATE(17,…) which ignores errors and blank cells automatically.
A30: All averages use AVERAGEIFS with >0 guard so empty rows are excluded from statistics.
A31: To extend the data area beyond 200 rows, add data to INPUT_DATA and the formulas update automatically.

Sheet KEY_COMPARABLES
A1: KEY COMPARABLES
A2: Enter an ID from INPUT_DATA in column A to auto-fill the row. Column H is for manual comments.
A4: ID | B4: Type | C4: Price | D4: Size | E4: Price per m² | F4: Condition | G4: Distance | H4: Comment (why it is relevant)
B5: =IF($A5="","",IFERROR(INDEX(INPUT_DATA!$B$2:$B$201,MATCH($A5,INPUT_DATA!$A$2:$A$201,0)),"not found")) | C5: =IF($A5="","",IFERROR(INDEX(INPUT_DATA!$F$2:$F$201,MATCH($A5,INPUT_DATA!$A$2:$A$201,0)),"not found")) | D5: =IF($A5="","",IFERROR(INDEX(INPUT_DATA!$G$2:$G$201,MATCH($A5,INPUT_DATA!$A$2:$A$201,0)),"not found")) | E5: =IF($A5="","",IFERROR(INDEX(INPUT_DATA!$H$2:$H$201,MATCH($A5,INPUT_DATA!$A$2:$A$201,0)),"not found")) | F5: =IF($A5="","",IFERROR(INDEX(INPUT_DATA!$M$2:$M$201,MATCH($A5,INPUT_DATA!$A$2:$A$201,0)),"not found")) | G5: =IF($A5="","",IFERROR(INDEX(INPUT_DATA!$E$2:$E$201,MATCH($A5,INPUT_DATA!$A$2:$A$201,0)),"not found"))
B6: =IF($A6="","",IFERROR(INDEX(INPUT_DATA!$B$2:$B$201,MATCH($A6,INPUT_DATA!$A$2:$A$201,0)),"not found")) | C6: =IF($A6="","",IFERROR(INDEX(INPUT_DATA!$F$2:$F$201,MATCH($A6,INPUT_DATA!$A$2:$A$201,0)),"not found")) | D6: =IF($A6="","",IFERROR(INDEX(INPUT_DATA!$G$2:$G$201,MATCH($A6,INPUT_DATA!$A$2:$A$201,0)),"not found")) | E6: =IF($A6="","",IFERROR(INDEX(INPUT_DATA!$H$2:$H$201,MATCH($A6,INPUT_DATA!$A$2:$A$201,0)),"not found")) | F6: =IF($A6="","",IFERROR(INDEX(INPUT_DATA!$M$2:$M$201,MATCH($A6,INPUT_DATA!$A$2:$A$201,0)),"not found")) | G6: =IF($A6="","",IFERROR(INDEX(INPUT_DATA!$E$2:$E$201,MATCH($A6,INPUT_DATA!$A$2:$A$201,0)),"not found"))
B7: =IF($A7="","",IFERROR(INDEX(INPUT_DATA!$B$2:$B$201,MATCH($A7,INPUT_DATA!$A$2:$A$201,0)),"not found")) | C7: =IF($A7="","",IFERROR(INDEX(INPUT_DATA!$F$2:$F$201,MATCH($A7,INPUT_DATA!$A$2:$A$201,0)),"not found")) | D7: =IF($A7="","",IFERROR(INDEX(INPUT_DATA!$G$2:$G$201,MATCH($A7,INPUT_DATA!$A$2:$A$201,0)),"not found")) | E7: =IF($A7="","",IFERROR(INDEX(INPUT_DATA!$H$2:$H$201,MATCH($A7,INPUT_DATA!$A$2:$A$201,0)),"not found")) | F7: =IF($A7="","",IFERROR(INDEX(INPUT_DATA!$M$2:$M$201,MATCH($A7,INPUT_DATA!$A$2:$A$201,0)),"not found")) | G7: =IF($A7="","",IFERROR(INDEX(INPUT_DATA!$E$2:$E$201,MATCH($A7,INPUT_DATA!$A$2:$A$201,0)),"not found"))
B8: =IF($A8="","",IFERROR(INDEX(INPUT_DATA!$B$2:$B$201,MATCH($A8,INPUT_DATA!$A$2:$A$201,0)),"not found")) | C8: =IF($A8="","",IFERROR(INDEX(INPUT_DATA!$F$2:$F$201,MATCH($A8,INPUT_DATA!$A$2:$A$201,0)),"not found")) | D8: =IF($A8="","",IFERROR(INDEX(INPUT_DATA!$G$2:$G$201,MATCH($A8,INPUT_DATA!$A$2:$A$201,0)),"not found")) | E8: =IF($A8="","",IFERROR(INDEX(INPUT_DATA!$H$2:$H$201,MATCH($A8,INPUT_DATA!$A$2:$A$201,0)),"not found")) | F8: =IF($A8="","",IFERROR(INDEX(INPUT_DATA!$M$2:$M$201,MATCH($A8,INPUT_DATA!$A$2:$A$201,0)),"not found")) | G8: =IF($A8="","",IFERROR(INDEX(INPUT_DATA!$E$2:$E$201,MATCH($A8,INPUT_DATA!$A$2:$A$201,0)),"not found"))
B9: =IF($A9="","",IFERROR(INDEX(INPUT_DATA!$B$2:$B$201,MATCH($A9,INPUT_DATA!$A$2:$A$201,0)),"not found")) | C9: =IF($A9="","",IFERROR(INDEX(INPUT_DATA!$F$2:$F$201,MATCH($A9,INPUT_DATA!$A$2:$A$201,0)),"not found")) | D9: =IF($A9="","",IFERROR(INDEX(INPUT_DATA!$G$2:$G$201,MATCH($A9,INPUT_DATA!$A$2:$A$201,0)),"not found")) | E9: =IF($A9="","",IFERROR(INDEX(INPUT_DATA!$H$2:$H$201,MATCH($A9,INPUT_DATA!$A$2:$A$201,0)),"not found")) | F9: =IF($A9="","",IFERROR(INDEX(INPUT_DATA!$M$2:$M$201,MATCH($A9,INPUT_DATA!$A$2:$A$201,0)),"not found")) | G9: =IF($A9="","",IFERROR(INDEX(INPUT_DATA!$E$2:$E$201,MATCH($A9,INPUT_DATA!$A$2:$A$201,0)),"not found"))
B10: =IF($A10="","",IFERROR(INDEX(INPUT_DATA!$B$2:$B$201,MATCH($A10,INPUT_DATA!$A$2:$A$201,0)),"not found")) | C10: =IF($A10="","",IFERROR(INDEX(INPUT_DATA!$F$2:$F$201,MATCH($A10,INPUT_DATA!$A$2:$A$201,0)),"not found")) | D10: =IF($A10="","",IFERROR(INDEX(INPUT_DATA!$G$2:$G$201,MATCH($A10,INPUT_DATA!$A$2:$A$201,0)),"not found")) | E10: =IF($A10="","",IFERROR(INDEX(INPUT_DATA!$H$2:$H$201,MATCH($A10,INPUT_DATA!$A$2:$A$201,0)),"not found")) | F10: =IF($A10="","",IFERROR(INDEX(INPUT_DATA!$M$2:$M$201,MATCH($A10,INPUT_DATA!$A$2:$A$201,0)),"not found")) | G10: =IF($A10="","",IFERROR(INDEX(INPUT_DATA!$E$2:$E$201,MATCH($A10,INPUT_DATA!$A$2:$A$201,0)),"not found"))
B11: =IF($A11="","",IFERROR(INDEX(INPUT_DATA!$B$2:$B$201,MATCH($A11,INPUT_DATA!$A$2:$A$201,0)),"not found")) | C11: =IF($A11="","",IFERROR(INDEX(INPUT_DATA!$F$2:$F$201,MATCH($A11,INPUT_DATA!$A$2:$A$201,0)),"not found")) | D11: =IF($A11="","",IFERROR(INDEX(INPUT_DATA!$G$2:$G$201,MATCH($A11,INPUT_DATA!$A$2:$A$201,0)),"not found")) | E11: =IF($A11="","",IFERROR(INDEX(INPUT_DATA!$H$2:$H$201,MATCH($A11,INPUT_DATA!$A$2:$A$201,0)),"not found")) | F11: =IF($A11="","",IFERROR(INDEX(INPUT_DATA!$M$2:$M$201,MATCH($A11,INPUT_DATA!$A$2:$A$201,0)),"not found")) | G11: =IF($A11="","",IFERROR(INDEX(INPUT_DATA!$E$2:$E$201,MATCH($A11,INPUT_DATA!$A$2:$A$201,0)),"not found"))
B12: =IF($A12="","",IFERROR(INDEX(INPUT_DATA!$B$2:$B$201,MATCH($A12,INPUT_DATA!$A$2:$A$201,0)),"not found")) | C12: =IF($A12="","",IFERROR(INDEX(INPUT_DATA!$F$2:$F$201,MATCH($A12,INPUT_DATA!$A$2:$A$201,0)),"not found")) | D12: =IF($A12="","",IFERROR(INDEX(INPUT_DATA!$G$2:$G$201,MATCH($A12,INPUT_DATA!$A$2:$A$201,0)),"not found")) | E12: =IF($A12="","",IFERROR(INDEX(INPUT_DATA!$H$2:$H$201,MATCH($A12,INPUT_DATA!$A$2:$A$201,0)),"not found")) | F12: =IF($A12="","",IFERROR(INDEX(INPUT_DATA!$M$2:$M$201,MATCH($A12,INPUT_DATA!$A$2:$A$201,0)),"not found")) | G12: =IF($A12="","",IFERROR(INDEX(INPUT_DATA!$E$2:$E$201,MATCH($A12,INPUT_DATA!$A$2:$A$201,0)),"not found"))
B13: =IF($A13="","",IFERROR(INDEX(INPUT_DATA!$B$2:$B$201,MATCH($A13,INPUT_DATA!$A$2:$A$201,0)),"not found")) | C13: =IF($A13="","",IFERROR(INDEX(INPUT_DATA!$F$2:$F$201,MATCH($A13,INPUT_DATA!$A$2:$A$201,0)),"not found")) | D13: =IF($A13="","",IFERROR(INDEX(INPUT_DATA!$G$2:$G$201,MATCH($A13,INPUT_DATA!$A$2:$A$201,0)),"not found")) | E13: =IF($A13="","",IFERROR(INDEX(INPUT_DATA!$H$2:$H$201,MATCH($A13,INPUT_DATA!$A$2:$A$201,0)),"not found")) | F13: =IF($A13="","",IFERROR(INDEX(INPUT_DATA!$M$2:$M$201,MATCH($A13,INPUT_DATA!$A$2:$A$201,0)),"not found")) | G13: =IF($A13="","",IFERROR(INDEX(INPUT_DATA!$E$2:$E$201,MATCH($A13,INPUT_DATA!$A$2:$A$201,0)),"not found"))
B14: =IF($A14="","",IFERROR(INDEX(INPUT_DATA!$B$2:$B$201,MATCH($A14,INPUT_DATA!$A$2:$A$201,0)),"not found")) | C14: =IF($A14="","",IFERROR(INDEX(INPUT_DATA!$F$2:$F$201,MATCH($A14,INPUT_DATA!$A$2:$A$201,0)),"not found")) | D14: =IF($A14="","",IFERROR(INDEX(INPUT_DATA!$G$2:$G$201,MATCH($A14,INPUT_DATA!$A$2:$A$201,0)),"not found")) | E14: =IF($A14="","",IFERROR(INDEX(INPUT_DATA!$H$2:$H$201,MATCH($A14,INPUT_DATA!$A$2:$A$201,0)),"not found")) | F14: =IF($A14="","",IFERROR(INDEX(INPUT_DATA!$M$2:$M$201,MATCH($A14,INPUT_DATA!$A$2:$A$201,0)),"not found")) | G14: =IF($A14="","",IFERROR(INDEX(INPUT_DATA!$E$2:$E$201,MATCH($A14,INPUT_DATA!$A$2:$A$201,0)),"not found"))
B15: =IF($A15="","",IFERROR(INDEX(INPUT_DATA!$B$2:$B$201,MATCH($A15,INPUT_DATA!$A$2:$A$201,0)),"not found")) | C15: =IF($A15="","",IFERROR(INDEX(INPUT_DATA!$F$2:$F$201,MATCH($A15,INPUT_DATA!$A$2:$A$201,0)),"not found")) | D15: =IF($A15="","",IFERROR(INDEX(INPUT_DATA!$G$2:$G$201,MATCH($A15,INPUT_DATA!$A$2:$A$201,0)),"not found")) | E15: =IF($A15="","",IFERROR(INDEX(INPUT_DATA!$H$2:$H$201,MATCH($A15,INPUT_DATA!$A$2:$A$201,0)),"not found")) | F15: =IF($A15="","",IFERROR(INDEX(INPUT_DATA!$M$2:$M$201,MATCH($A15,INPUT_DATA!$A$2:$A$201,0)),"not found")) | G15: =IF($A15="","",IFERROR(INDEX(INPUT_DATA!$E$2:$E$201,MATCH($A15,INPUT_DATA!$A$2:$A$201,0)),"not found"))
B16: =IF($A16="","",IFERROR(INDEX(INPUT_DATA!$B$2:$B$201,MATCH($A16,INPUT_DATA!$A$2:$A$201,0)),"not found")) | C16: =IF($A16="","",IFERROR(INDEX(INPUT_DATA!$F$2:$F$201,MATCH($A16,INPUT_DATA!$A$2:$A$201,0)),"not found")) | D16: =IF($A16="","",IFERROR(INDEX(INPUT_DATA!$G$2:$G$201,MATCH($A16,INPUT_DATA!$A$2:$A$201,0)),"not found")) | E16: =IF($A16="","",IFERROR(INDEX(INPUT_DATA!$H$2:$H$201,MATCH($A16,INPUT_DATA!$A$2:$A$201,0)),"not found")) | F16: =IF($A16="","",IFERROR(INDEX(INPUT_DATA!$M$2:$M$201,MATCH($A16,INPUT_DATA!$A$2:$A$201,0)),"not found")) | G16: =IF($A16="","",IFERROR(INDEX(INPUT_DATA!$E$2:$E$201,MATCH($A16,INPUT_DATA!$A$2:$A$201,0)),"not found"))
... B24: =IF($A24="","",IFERROR(INDEX(INPUT_DATA!$B$2:$B$201,MATCH($A24,INPUT_DATA!$A$2:$A$201,0)),"not found")) | C24: =IF($A24="","",IFERROR(INDEX(INPUT_DATA!$F$2:$F$201,MATCH($A24,INPUT_DATA!$A$2:$A$201,0)),"not found")) | D24: =IF($A24="","",IFERROR(INDEX(INPUT_DATA!$G$2:$G$201,MATCH($A24,INPUT_DATA!$A$2:$A$201,0)),"not found")) | E24: =IF($A24="","",IFERROR(INDEX(INPUT_DATA!$H$2:$H$201,MATCH($A24,INPUT_DATA!$A$2:$A$201,0)),"not found")) | F24: =IF($A24="","",IFERROR(INDEX(INPUT_DATA!$M$2:$M$201,MATCH($A24,INPUT_DATA!$A$2:$A$201,0)),"not found")) | G24: =IF($A24="","",IFERROR(INDEX(INPUT_DATA!$E$2:$E$201,MATCH($A24,INPUT_DATA!$A$2:$A$201,0)),"not found"))
